Workbook

Sheet 2023_Fabio
H1: Entradas
N2: Cheque Especial | O2: -840
A3: Cod | B3: Descrição | C3: Janeiro | D3: Fevereiro | E3: Março | F3: Abril | G3: Maio | H3: Junho | I3: Julho | J3: Agosto | K3: Setembro | L3: Outubro | M3: Novembro | N3: Dezembro
A4: 1 | B4: Saldo Mês Anterior | D4: =C33 -> 5511.93 | E4: =D33 -> 22023.86 | F4: =E33 -> 28535.79 | G4: =F33 -> 35047.72 | H4: =G33 -> -755.51 | I4: =H33 -> -1198.82 | J4: =I33 -> -1743.45 | K4: =J33 -> -1696.34 | ... N4: =M33 -> 3108.71
A5: 2 | B5: Sal. Fabio | C5: =3562.93+541.52 -> 4104.45 | D5: =3562.93+541.52 -> 4104.45 | E5: =3562.93+541.52 -> 4104.45 | F5: =3562.93+541.52 -> 4104.45 | G5: =3562.93+541.52 -> 4104.45 | H5: =3783.85+541.52 -> 4325.37 | I5: =4104.45 -> 4104.45 | J5: =4104.45 -> 4104.45 | K5: =4104.45 -> 4104.45 | L5: =4104.45 -> 4104.45 | M5: =4104.45 -> 4104.45 | N5: =4104.45 -> 4104.45
A6: 3 | B6: Sal Extra | C6: 1500 | D6: =10000+2500 -> 12500 | E6: 2500 | F6: 2500 | H6: =94.7+1.77 -> 96.47 | K6: =(2572,21+1714,81)-643,06
A7: 4 | B7: Empresa | C7: 449 | D7: 449 | E7: 449 | F7: 449 | G7: 449 | H7: 449 | I7: 449 | J7: 449 | K7: 449 | L7: 449 | M7: 449 | N7: 449
A8: 5 | B8: Outros | H8: =2600+246+200 -> 3046 | M8: 2000 | N8: 1500
B9: Saldo Entrada | C9: =SUM(C4:C8) -> 6053.45 | D9: =SUM(D4:D8) -> 22565.38 | E9: =SUM(E4:E8) -> 29077.31 | F9: =SUM(F4:F8) -> 35589.24 | G9: =SUM(G4:G8) -> 39601.17 | H9: =SUM(H4:H8) -> 7161.33 | I9: =SUM(I4:I8) -> 3354.63 | J9: =SUM(J4:J8) -> 2810 | ... N9: =SUM(N4:N8) -> 9162.16
B10: Total Entrada | C10: =sum(C5:C8) -> 6053.45 | D10: =sum(D5:D8) -> 17053.45 | E10: =sum(E5:E8) -> 7053.45 | F10: =sum(F5:F8) -> 7053.45 | G10: =sum(G5:G8) -> 4553.45 | H10: =sum(H5:H8) -> 7916.84 | I10: =sum(I5:I8) -> 4553.45 | J10: =sum(J5:J8) -> 4553.45 | ... N10: =sum(N5:N8) -> 6053.45
H12: Saídas
A13: Cod | B13: Descrição | C13: Janeiro | D13: Fevereiro | E13: Março | F13: Abril | G13: Maio | H13: Junho | I13: Julho | J13: Agosto | K13: Setembro | L13: Outubro | M13: Novembro | N13: Dezembro | O13: Total no Ano
A14: 1 | B14: Casa | H14: 368 | I14: 368 | J14: 368 | K14: 368 | L14: 368 | M14: 368 | N14: 368 | O14: =sum(C14:N14) -> 2576
A15: 2 | B15: Condomínio | H15: 336 | I15: 336 | J15: 336 | K15: 336 | L15: 336 | M15: 336 | N15: 336 | O15: =sum(C15:N15) -> 2352
A16: 3 | B16: NET | H16: 270 | I16: 270 | J16: 270 | K16: 270 | L16: 270 | M16: 270 | N16: 270 | O16: =sum(C16:N16) -> 1890
A17: 4 | B17: Celular | H17: 140 | I17: 140 | J17: 140 | K17: 140 | L17: 140 | M17: 140 | N17: 140 | O17: =sum(C17:N17) -> 980
A18: 5 | B18: Card Carrefour | H18: 531.41 | I18: =14.99+14.9+6.9+105+150 -> 291.79 | J18: =14.99+14.9 -> 29.89 | K18: =14.99+14.9 -> 29.89 | L18: =14.99+14.9 -> 29.89 | M18: =14.99+14.9 -> 29.89 | N18: =14.99+14.9 -> 29.89 | O18: =sum(C18:N18) -> 972.65
A19: 6 | B19: Card Trigg | H19: 1506.88 | I19: =411.56+325.85+(20*5.7)+14.99 -> 866.4 | J19: =342.09+325.85+(20*5.7)+14.99 -> 796.93 | K19: =224.29+325.85+(20*5.7)+14.99 -> 679.13 | L19: =224.29+(20*5.7)+14.99 -> 353.28 | M19: =224.29+(20*5.7)+14.99 -> 353.28 | N19: =201.39+(20*5.7)+14.99 -> 330.38 | O19: =sum(C19:N19) -> 4886.28
A20: 7 | B20: Card NuBank | H20: =337.23 -> 337.23 | I20: =57.25+39.9+20 -> 117.15 | J20: =39.9+20 -> 59.9 | K20: =39.9+20 -> 59.9 | L20: =39.9+20 -> 59.9 | M20: =39.9+20 -> 59.9 | N20: =39.9+20 -> 59.9 | O20: =sum(C20:N20) -> 753.88
A21: 8 | B21: Card Neon | H21: 897.44 | I21: =159.14+((15+7.4+6.9+8+40)*8) -> 777.54 | J21: =159.14+230 -> 389.14 | K21: 159.14 | L21: 111.16 | O21: =sum(C21:N21) -> 2334.42
A22: 9 | B22: Card C6 | H22: =2462.62+48.89+83.35+7.4+6.9 -> 2609.16 | I22: 618.86 | J22: 505.39 | K22: 505.39 | L22: 505.39 | M22: 505.39 | N22: 505.39 | O22: =sum(C22:N22) -> 5754.97
A23: 10 | B23: Card PAN | H23: 89.18 | O23: =sum(C23:N23) -> 89.18
A24: 11 | B24: Empréstimo | C24: =541.52 -> 541.52 | D24: =541.52 -> 541.52 | E24: =541.52 -> 541.52 | F24: =541.52 -> 541.52 | G24: =541.52 -> 541.52 | H24: =541.52 -> 541.52 | I24: 104 | J24: 104 | O24: =sum(C24:N24) -> 3457.12
A25: 12 | B25: Presencial | G25: =30+16+37.47+43.99+25.35+37.47+32.9 -> 223.18 | H25: 68.75 | I25: =(15+7.4+6.9+8+40)*8 -> 618.4 | J25: =68.75+(15+7.4+6.9+8+40)*8 -> 687.15 | K25: =(15+7.4+6.9+8+40)*8 -> 618.4 | L25: =68.75+(15+7.4+6.9+8+40)*8 -> 687.15 | M25: =(15+7.4+6.9+8+40)*8 -> 618.4 | N25: =68.75+(15+7.4+6.9+8+40)*8 -> 687.15 | O25: =sum(C25:N25) -> 4208.58
A26: 13 | B26: Pets | G26: =20.01 -> 20.01 | J26: =150+80 -> 230 | K26: =150+80 -> 230 | L26: =150+80 -> 230 | M26: =150+80 -> 230 | N26: =150+80 -> 230 | O26: =sum(C26:N26) -> 1170.01
A27: 14 | B27: Outros | G27: =30+24.99+100+23.48+8.22 -> 186.69 | H27: =30+30 -> 60 | I27: 60 | J27: =60 -> 60 | K27: =60 -> 60 | L27: =60 -> 60 | M27: =60 -> 60 | N27: =60 -> 60 | O27: =sum(C27:N27) -> 606.69
A28: 15 | B28: Uber | I28: 104 | J28: 104 | O28: =sum(C28:N28) -> 208
A29: 16 | B29: Acordo | G29: =328.71 -> 328.71 | H29: =325.94+198.84 -> 524.78 | I29: 325.94 | J29: 325.94 | K29: 325.94 | L29: 325.94 | M29: 325.94 | N29: 325.94 | O29: =sum(C29:N29) -> 2809.13
A30: 17 | B30: Academia | I30: 100 | J30: 100 | K30: 100 | L30: 100 | M30: 100 | N30: 100 | O30: =sum(C30:N30) -> 600
A31: 18 | B31: Complemento | G31: =39056.57+((20.3+2.8)*0) -> 39056.57 | H31: 79.8 | O31: =sum(C31:N31) -> 39136.37
B32: Total Saída | C32: =SUM(C14:C31) -> 541.52 | D32: =SUM(D14:D31) -> 541.52 | E32: =SUM(E14:E31) -> 541.52 | F32: =SUM(F14:F31) -> 541.52 | G32: =SUM(G14:G31) -> 40356.68 | H32: =SUM(H14:H31) -> 8360.15 | I32: =SUM(I14:I31) -> 5098.08 | J32: =SUM(J14:J31) -> 4506.34 | ... N32: =SUM(N14:N31) -> 3442.65 | O32: =sum(C32:N32) -> 74785.28
B33: Saldo | C33: =C9-C32 -> 5511.93 | D33: =D9-D32 -> 22023.86 | E33: =E9-E32 -> 28535.79 | F33: =F9-F32 -> 35047.72 | G33: =G9-G32 -> -755.51 | H33: =H9-H32 -> -1198.82 | I33: =I9-I32 -> -1743.45 | J33: =J9-J32 -> -1696.34 | ... N33: =N9-N32 -> 5719.51
B35: Saldo total mês | C35: =sum(C5:C8)-sum(C14:C31) -> 5511.93 | D35: =sum(D5:D8)-sum(D14:D31) -> 16511.93 | E35: =sum(E5:E8)-sum(E14:E31) -> 6511.93 | F35: =sum(F5:F8)-sum(F14:F31) -> 6511.93 | G35: =sum(G5:G8)-sum(G14:G31) -> -35803.23 | H35: =sum(H5:H8)-sum(H14:H31) -> -443.31 | I35: =sum(I5:I8)-sum(I14:I31) -> -544.63 | J35: =sum(J5:J8)-sum(J14:J31) -> 47.11 | ... N35: =sum(N5:N8)-sum(N14:N31) -> 2610.8 | O35: =sum(C35:N35) -> 5719.51
B36: Saldo Cheque Especial | C36: =if(and(C33>$O$2,C33>0),$O$2*(-1),C33-$O$2) -> 840 | D36: =if(and(D33>$O$2,D33>0),$O$2*(-1),D33-$O$2) -> 840 | E36: =if(and(E33>$O$2,E33>0),$O$2*(-1),E33-$O$2) -> 840 | F36: =if(and(F33>$O$2,F33>0),$O$2*(-1),F33-$O$2) -> 840 | G36: =if(and(G33>$O$2,G33>0),$O$2*(-1),G33-$O$2) -> 84.49 | H36: =if(and(H33>$O$2,H33>0),$O$2*(-1),H33-$O$2) -> -358.82 | I36: =if(and(I33>$O$2,I33>0),$O$2*(-1),I33-$O$2) -> -903.45 | J36: =if(and(J33>$O$2,J33>0),$O$2*(-1),J33-$O$2) -> -856.34 | ... N36: =if(and(N33>$O$2,N33>0),$O$2*(-1),N33-$O$2) -> 840
C38: Créditos no ano | F38: Débitos no ano | I38: Saldo no ano
C39: =SUM(C10:N10)+sum(C7:N7) -> 85892.79 | F39: =SUM(C32:N32)-sum(C25:N25) -> 70576.7 | I39: =C39-F39 -> 15316.09
G41: =G31+1.77 -> 39058.34 | H41: =H33-L38 -> -1198.82

Sheet 2022_Fabio
H1: Entradas
B2: FECHAMENTO | O2: 44600
A3: Cod | B3: Descrição | C3: Janeiro | D3: Fevereiro | E3: Março | F3: Abril | G3: Maio | H3: Junho | I3: Julho | J3: Agosto | K3: Setembro | L3: Outubro | M3: Novembro | N3: Dezembro
A4: 1 | B4: Saldo Mês Anterior | C4: 105.61 | D4: =C32 -> 105.61 | E4: =D32 -> 1084.14 | F4: =E32 -> 2853.28 | G4: =F32 -> 5019.94 | H4: =G32 -> 7257.6 | I4: =H32 -> 9495.26 | J4: =I32 -> 11732.92 | K4: =J32 -> 13970.58 | ... N4: =M32 -> 26897.51
A5: 2 | B5: Sal. Fabio | C5: 3546 | D5: =3558+4393 -> 7951 | E5: 3546 | F5: 3546 | G5: 3546 | H5: 3546 | I5: 3546 | J5: 3546 | K5: 3546 | L5: 3546 | M5: 3546 | N5: =3546*2 -> 7092
A6: 3 | B6: Pag. Empréstimo Melyssa
A7: 4 | B7: Empresa | C7: 580 | D7: =100+80+82.5+80+49.9 -> 392.4 | E7: 629.9 | F7: 629.9 | G7: 629.9 | H7: 629.9 | I7: 629.9 | J7: 629.9 | K7: 629.9 | L7: 629.9 | M7: 629.9 | N7: 629.9
A8: 5 | B8: Outros | D8: =4.01+4.5+0.06 -> 8.57 | L8: 5731.39
B9: Saldo Entrada | C9: =SUM(C4:C8) -> 4231.61 | D9: =SUM(D4:D8) -> 8457.58 | E9: =SUM(E4:E8) -> 5260.04 | F9: =SUM(F4:F8) -> 7029.18 | G9: =SUM(G4:G8) -> 9195.84 | H9: =SUM(H4:H8) -> 11433.5 | I9: =SUM(I4:I8) -> 13671.16 | J9: =SUM(J4:J8) -> 15908.82 | ... N9: =SUM(N4:N8) -> 34619.41
B10: Total Entrada | C10: =sum(C5:C8) -> 4126 | D10: =sum(D5:D8) -> 8351.97 | E10: =sum(E5:E8) -> 4175.9 | F10: =sum(F5:F8) -> 4175.9 | G10: =sum(G5:G8) -> 4175.9 | H10: =sum(H5:H8) -> 4175.9 | I10: =sum(I5:I8) -> 4175.9 | J10: =sum(J5:J8) -> 4175.9 | ... N10: =sum(N5:N8) -> 7721.9
H12: Saídas
A13: Cod | B13: Descrição | C13: Janeiro | D13: Fevereiro | E13: Março | F13: Abril | G13: Maio | H13: Junho | I13: Julho | J13: Agosto | K13: Setembro | L13: Outubro | M13: Novembro | N13: Dezembro | O13: Total no Ano
A14: 1 | B14: Casa | C14: 367 | D14: 364.16 | E14: 360 | F14: 360 | G14: 360 | H14: 360 | I14: 360 | J14: 360 | K14: 360 | L14: 360 | M14: 360 | N14: 360 | O14: =sum(C14:N14) -> 4331.16
A15: 2 | B15: Condomínio | C15: 0 | D15: =273.17+209.36 -> 482.53 | E15: 209.36 | F15: 209.36 | G15: 209.36 | H15: 209.36 | I15: 209.36 | J15: 209.36 | K15: 209.36 | L15: 209.36 | M15: 209.36 | N15: 209.36 | O15: =sum(C15:N15) -> 2576.13
A16: 3 | B16: Live Tim | C16: 125 | D16: 125 | E16: 130 | F16: 130 | G16: 130 | H16: 130 | I16: 130 | J16: 130 | K16: 130 | L16: 130 | M16: 130 | N16: 130 | O16: =sum(C16:N16) -> 1550
A17: 4 | B17: Internet Sepetiba | C17: 100 | D17: 80 | E17: 80 | F17: 80 | G17: 80 | H17: 80 | I17: 80 | J17: 80 | K17: 80 | L17: 80 | M17: 80 | N17: 80 | O17: =sum(C17:N17) -> 980
A18: 5 | B18: Santander | C18: 241.28 | D18: 241.28 | E18: 241.28 | F18: 241.28 | G18: 241.28 | H18: 241.28 | I18: 241.28 | J18: 241.28 | K18: 241.28 | O18: =sum(C18:N18) -> 2171.52
A19: 6 | B19: Card NuBank | D19: 398.87 | E19: =30.15+39.9+40+30+22.93+12.09+15.94+7.4+24.97+40.59+19.98+10.98+3+28.9+13.9+30.94+14.95+10.9 -> 397.52 | O19: =sum(C19:N19) -> 796.39
A20: 7 | B20: Itaú | C20: 71 | D20: 69.85 | E20: 71 | F20: 71 | O20: =sum(C20:N20) -> 282.85
A21: 8 | B21: Celular | C21: 30 | D21: =15+20 -> 35 | E21: 30 | F21: 30 | G21: 30 | H21: 30 | I21: 30 | J21: 30 | K21: 30 | L21: 30 | M21: 30 | N21: 30 | O21: =sum(C21:N21) -> 365
A22: 9 | B22: Serviços Streaming | D22: =24.9 -> 24.9 | E22: =24.9+39.9 -> 64.8 | F22: =24.9+39.9 -> 64.8 | G22: =24.9+39.9 -> 64.8 | H22: =24.9+39.9 -> 64.8 | I22: =24.9+39.9 -> 64.8 | J22: =24.9+39.9 -> 64.8 | K22: =24.9+39.9 -> 64.8 | L22: =24.9+39.9 -> 64.8 | ... N22: =24.9+39.9 -> 64.8 | O22: =sum(C22:N22) -> 672.9
A23: 10 | B23: Esposa | O23: =sum(C23:N23) -> 0
A24: 11 | B24: Empréstimo para Melyssa | O24: =sum(C24:N24) -> 0
A25: 12 | B25: Pets | C25: 235 | D25: =147.9+20+20 -> 187.9 | E25: =155+80 -> 235 | F25: =155+80 -> 235 | G25: =155+80 -> 235 | H25: =155+80 -> 235 | I25: =155+80 -> 235 | J25: =155+80 -> 235 | K25: =155+80 -> 235 | L25: =155+80 -> 235 | ... N25: =155+80 -> 235 | O25: =sum(C25:N25) -> 2772.9
A26: 13 | B26: Rolé | C26: 200 | D26: =64+49.86+86+65+40+55+34+18.48 -> 412.34 | O26: =sum(C26:N26) -> 612.34
A27: 14 | B27: Uber | C27: 500 | D27: =SUMIFS('Registros Detalhados'!$A:$A,'Registros Detalhados'!$B:$B,$B$27,'Registros Detalhados'!$D:$D,D13) -> 909.12 | E27: =SUMIFS('Registros Detalhados'!$A:$A,'Registros Detalhados'!$B:$B,$B$27,'Registros Detalhados'!$D:$D,E13) -> 500 | F27: =SUMIFS('Registros Detalhados'!$A:$A,'Registros Detalhados'!$B:$B,$B$27,'Registros Detalhados'!$D:$D,F13) -> 500 | G27: =SUMIFS('Registros Detalhados'!$A:$A,'Registros Detalhados'!$B:$B,$B$27,'Registros Detalhados'!$D:$D,G13) -> 500 | H27: =SUMIFS('Registros Detalhados'!$A:$A,'Registros Detalhados'!$B:$B,$B$27,'Registros Detalhados'!$D:$D,H13) -> 500 | I27: =SUMIFS('Registros Detalhados'!$A:$A,'Registros Detalhados'!$B:$B,$B$27,'Registros Detalhados'!$D:$D,I13) -> 500 | J27: =SUMIFS('Registros Detalhados'!$A:$A,'Registros Detalhados'!$B:$B,$B$27,'Registros Detalhados'!$D:$D,J13) -> 500 | K27: =SUMIFS('Registros Detalhados'!$A:$A,'Registros Detalhados'!$B:$B,$B$27,'Registros Detalhados'!$D:$D,K13) -> 500 | ... N27: =SUMIFS('Registros Detalhados'!$A:$A,'Registros Detalhados'!$B:$B,$B$27,'Registros Detalhados'!$D:$D,N13) -> 500 | O27: =sum(C27:N27) -> 6409.12
A28: 15 | B28: Plano Dental - Pais | C28: 87.5 | D28: 87.8 | E28: 87.8 | F28: 87.8 | G28: 87.8 | H28: 87.8 | I28: 87.8 | J28: 87.8 | K28: 87.8 | L28: 87.8 | M28: 87.8 | N28: 87.8 | O28: =sum(C28:N28) -> 1053.3
A29: 16 | B29: Alimentação | D29: =9.97+15+1.39+10.14+10.77+46+9+32+28+15+5.77+3.59+5.39+9.68+29.85+7.18+6.68+5.39 -> 250.8 | O29: =sum(C29:N29) -> 250.8
A30: 17 | B30: Outros | C30: =500+400+1269.22 -> 2169.22 | D30: =2754+500+16.96+12.9+15+4.2+35.08+30+17.99+97.93+25.8+14+15.07+6+12+60+25+25+18.99+15+2.97 -> 3703.89 | O30: =sum(C30:N30) -> 5873.11
B31: Total Saída | C31: =SUM(C14:C30) -> 4126 | D31: =SUM(D14:D30) -> 7373.44 | E31: =SUM(E14:E30) -> 2406.76 | F31: =SUM(F14:F30) -> 2009.24 | G31: =SUM(G14:G30) -> 1938.24 | H31: =SUM(H14:H30) -> 1938.24 | I31: =SUM(I14:I30) -> 1938.24 | J31: =SUM(J14:J30) -> 1938.24 | ... N31: =SUM(N14:N30) -> 1696.96 | O31: =sum(C31:N31) -> 30697.52
B32: Saldo | C32: =C9-C31 -> 105.61 | D32: =D9-D31 -> 1084.14 | E32: =E9-E31 -> 2853.28 | F32: =F9-F31 -> 5019.94 | G32: =G9-G31 -> 7257.6 | H32: =H9-H31 -> 9495.26 | I32: =I9-I31 -> 11732.92 | J32: =J9-J31 -> 13970.58 | ... N32: =N9-N31 -> 32922.45
B34: Saldo total mês | C34: =sum(C5:C8)-sum(C14:C30) -> 0 | D34: =sum(D5:D8)-sum(D14:D30) -> 978.53 | E34: =sum(E5:E8)-sum(E14:E30) -> 1769.14 | F34: =sum(F5:F8)-sum(F14:F30) -> 2166.66 | G34: =sum(G5:G8)-sum(G14:G30) -> 2237.66 | H34: =sum(H5:H8)-sum(H14:H30) -> 2237.66 | I34: =sum(I5:I8)-sum(I14:I30) -> 2237.66 | J34: =sum(J5:J8)-sum(J14:J30) -> 2237.66 | ... N34: =sum(N5:N8)-sum(N14:N30) -> 6024.94 | O34: =sum(C34:N34) -> 32816.84
C36: Créditos no ano | F36: Débitos no ano | I36: Saldo no ano
C37: =SUM(C10:N10)+sum(C7:N7) -> 70785.76 | F37: =SUM(C31:N31)-sum(C24:N24) -> 30697.52 | I37: =C37-F37 -> 40088.24
B38: 2 | D38: =(D31+'2022_Mely'!C40)-'2022_Mely'!C7-'2022_Mely'!C8 -> #REF!
B39: 9.61
B40: 18.15 | C40: =D32- sum(B38:B40) -> 1054.38

Sheet Registros Detalhados
A1: Fabio
A2: Histórico | B2: Categoria | C2: Data | D2: Mês | F2: N | G2: Mês
A3: 15.47 | B3: Uber | C3: 44593 | D3: =if(COUNTBLANK(C3),"",VLOOKUP(MONTH(C3),$F$2:$G$14,2)) -> fevereiro | F3: 1 | G3: Janeiro
A4: 28.99 | B4: Uber | C4: 44594 | D4: =if(COUNTBLANK(C4),"",VLOOKUP(MONTH(C4),$F$2:$G$14,2)) -> fevereiro | F4: 2 | G4: fevereiro
A5: 26.28 | B5: Uber | C5: 44594 | D5: =if(COUNTBLANK(C5),"",VLOOKUP(MONTH(C5),$F$2:$G$14,2)) -> fevereiro | F5: 3 | G5: março
A6: 21.49 | B6: Uber | C6: 44594 | D6: =if(COUNTBLANK(C6),"",VLOOKUP(MONTH(C6),$F$2:$G$14,2)) -> fevereiro | F6: 4 | G6: abril
A7: 27.07 | B7: Uber | C7: 44594 | D7: =if(COUNTBLANK(C7),"",VLOOKUP(MONTH(C7),$F$2:$G$14,2)) -> fevereiro | F7: 5 | G7: maio
A8: 7.68 | B8: Uber | C8: 44594 | D8: =if(COUNTBLANK(C8),"",VLOOKUP(MONTH(C8),$F$2:$G$14,2)) -> fevereiro | F8: 6 | G8: junho
A9: 39.97 | B9: Uber | C9: 44594 | D9: =if(COUNTBLANK(C9),"",VLOOKUP(MONTH(C9),$F$2:$G$14,2)) -> fevereiro | F9: 7 | G9: julho
A10: 30.21 | B10: Uber | C10: 44594 | D10: =if(COUNTBLANK(C10),"",VLOOKUP(MONTH(C10),$F$2:$G$14,2)) -> fevereiro | F10: 8 | G10: agosto
A11: 17.09 | B11: Uber | C11: 44594 | D11: =if(COUNTBLANK(C11),"",VLOOKUP(MONTH(C11),$F$2:$G$14,2)) -> fevereiro | F11: 9 | G11: setembro
A12: 35.96 | B12: Uber | C12: 44594 | D12: =if(COUNTBLANK(C12),"",VLOOKUP(MONTH(C12),$F$2:$G$14,2)) -> fevereiro | F12: 10 | G12: outubro
A13: 19.93 | B13: Uber | C13: 44594 | D13: =if(COUNTBLANK(C13),"",VLOOKUP(MONTH(C13),$F$2:$G$14,2)) -> fevereiro | F13: 11 | G13: novembro
A14: 10 | B14: Uber | C14: 44594 | D14: =if(COUNTBLANK(C14),"",VLOOKUP(MONTH(C14),$F$2:$G$14,2)) -> fevereiro | F14: 12 | G14: dezembro
A15: 14 | B15: Uber | C15: 44594 | D15: =if(COUNTBLANK(C15),"",VLOOKUP(MONTH(C15),$F$2:$G$14,2)) -> fevereiro
A16: 26.16 | B16: Uber | C16: 44594 | D16: =if(COUNTBLANK(C16),"",VLOOKUP(MONTH(C16),$F$2:$G$14,2)) -> fevereiro
A17: 11.97 | B17: Uber | C17: 44594 | D17: =if(COUNTBLANK(C17),"",VLOOKUP(MONTH(C17),$F$2:$G$14,2)) -> fevereiro
A18: 24.91 | B18: Uber | C18: 44594 | D18: =if(COUNTBLANK(C18),"",VLOOKUP(MONTH(C18),$F$2:$G$14,2)) -> fevereiro
A19: 35.79 | B19: Uber | C19: 44594 | D19: =if(COUNTBLANK(C19),"",VLOOKUP(MONTH(C19),$F$2:$G$14,2)) -> fevereiro
A20: 18.91 | B20: Uber | C20: 44594 | D20: =if(COUNTBLANK(C20),"",VLOOKUP(MONTH(C20),$F$2:$G$14,2)) -> fevereiro
A21: 14.97 | B21: Uber | C21: 44594 | D21: =if(COUNTBLANK(C21),"",VLOOKUP(MONTH(C21),$F$2:$G$14,2)) -> fevereiro
A22: 34.31 | B22: Uber | C22: 44594 | D22: =if(COUNTBLANK(C22),"",VLOOKUP(MONTH(C22),$F$2:$G$14,2)) -> fevereiro
A23: 7.48 | B23: Uber | C23: 44594 | D23: =if(COUNTBLANK(C23),"",VLOOKUP(MONTH(C23),$F$2:$G$14,2)) -> fevereiro
A24: 11.47 | B24: Uber | C24: 44594 | D24: =if(COUNTBLANK(C24),"",VLOOKUP(MONTH(C24),$F$2:$G$14,2)) -> fevereiro
A25: 9.94 | B25: Uber | C25: 44594 | D25: =if(COUNTBLANK(C25),"",VLOOKUP(MONTH(C25),$F$2:$G$14,2)) -> fevereiro
A26: 32.49 | B26: Uber | C26: 44594 | D26: =if(COUNTBLANK(C26),"",VLOOKUP(MONTH(C26),$F$2:$G$14,2)) -> fevereiro
... A46: 29.92 | B46: Uber | C46: 44604 | D46: =if(COUNTBLANK(C46),"",VLOOKUP(MONTH(C46),$F$2:$G$14,2)) -> fevereiro
D47: =if(COUNTBLANK(C47),"",VLOOKUP(MONTH(C47),$F$2:$G$14,2))
D48: =if(COUNTBLANK(C48),"",VLOOKUP(MONTH(C48),$F$2:$G$14,2))
D49: =if(COUNTBLANK(C49),"",VLOOKUP(MONTH(C49),$F$2:$G$14,2))
D50: =if(COUNTBLANK(C50),"",VLOOKUP(MONTH(C50),$F$2:$G$14,2))
D51: =if(COUNTBLANK(C51),"",VLOOKUP(MONTH(C51),$F$2:$G$14,2))
D52: =if(COUNTBLANK(C52),"",VLOOKUP(MONTH(C52),$F$2:$G$14,2))
D53: =if(COUNTBLANK(C53),"",VLOOKUP(MONTH(C53),$F$2:$G$14,2))
A54: 500 | B54: Uber | C54: 44896 | D54: =if(COUNTBLANK(C54),"",VLOOKUP(MONTH(C54),$F$2:$G$14,2)) -> dezembro
A55: 500 | B55: Uber | C55: 44866 | D55: =if(COUNTBLANK(C55),"",VLOOKUP(MONTH(C55),$F$2:$G$14,2)) -> novembro
A56: 500 | B56: Uber | C56: 44835 | D56: =if(COUNTBLANK(C56),"",VLOOKUP(MONTH(C56),$F$2:$G$14,2)) -> outubro
A57: 500 | B57: Uber | C57: 44621 | D57: =if(COUNTBLANK(C57),"",VLOOKUP(MONTH(C57),$F$2:$G$14,2)) -> março
A58: 500 | B58: Uber | C58: 44653 | D58: =if(COUNTBLANK(C58),"",VLOOKUP(MONTH(C58),$F$2:$G$14,2)) -> abril
A59: 500 | B59: Uber | C59: 44684 | D59: =if(COUNTBLANK(C59),"",VLOOKUP(MONTH(C59),$F$2:$G$14,2)) -> maio
...
